Feature: modify event on event filter
  I need to be able to modify event on event filter

  @concurrent
  Scenario: given check event and enrich from external api data with unauth error should create failure
    Given I am admin
    When I do POST /api/v4/eventfilter/rules:
    """json
    {
      "type": "enrichment",
      "description": "test-event-filter-che-event-filters-failure-api-1-description",
      "enabled": true,
      "event_pattern": [
        [
          {
            "field": "component",
            "cond": {
              "type": "eq",
              "value": "test-component-che-event-filters-failure-api-1"
            }
          },
          {
            "field": "event_type",
            "cond": {
              "type": "eq",
              "value": "check"
            }
          }
        ]
      ],
      "external_data": {
        "title": {
          "type": "api",
          "request": {
            "url": "{{ .dummyApiURL }}/webhook/auth-request",
            "method": "POST",
            "retry_count": 0
          }
        }
      },
      "config": {
        "actions": [
          {
            "type": "set_field_from_template",
            "name": "title",
            "value": "{{ `{{.ExternalData.title.title}}` }}"
          }
        ],
        "on_success": "pass",
        "on_failure": "pass"
      }
    }
    """
    Then the response code should be 201
    Then I save response ruleId={{ .lastResponse._id }}
    When I wait the next periodical process
    When I send an event and wait the end of event processing:
    """json
    [
      {
        "event_type": "check",
        "state": 2,
        "output": "test-output-che-event-filters-failure-api-1",
        "connector": "test-connector-che-event-filters-failure-api-1",
        "connector_name": "test-connector-name-che-event-filters-failure-api-1",
        "component": "test-component-che-event-filters-failure-api-1",
        "resource": "test-resource-che-event-filters-failure-api-1-1",
        "source_type": "resource"
      },
      {
        "event_type": "check",
        "state": 2,
        "output": "test-output-che-event-filters-failure-api-1",
        "connector": "test-connector-che-event-filters-failure-api-1",
        "connector_name": "test-connector-name-che-event-filters-failure-api-1",
        "component": "test-component-che-event-filters-failure-api-1",
        "resource": "test-resource-che-event-filters-failure-api-1-2",
        "source_type": "resource"
      }
    ]
    """
    When I do GET /api/v4/eventfilter/{{ .ruleId }}/failures until response code is 200 and body contains:
    """json
    {
      "data": [
        {
          "type": 3,
          "message": "external data \"title\" cannot be fetched: url {{ .dummyApiURL }}/webhook/auth-request is unauthorized",
          "event": {
            "connector": "test-connector-che-event-filters-failure-api-1",
            "connector_name": "test-connector-name-che-event-filters-failure-api-1",
            "component": "test-component-che-event-filters-failure-api-1",
            "source_type": "resource"
          },
          "unread": true
        },
        {
          "type": 3,
          "message": "external data \"title\" cannot be fetched: url {{ .dummyApiURL }}/webhook/auth-request is unauthorized",
          "event": {
            "connector": "test-connector-che-event-filters-failure-api-1",
            "connector_name": "test-connector-name-che-event-filters-failure-api-1",
            "component": "test-component-che-event-filters-failure-api-1",
            "source_type": "resource"
          },
          "unread": true
        }
      ],
      "meta": {
        "page": 1,
        "page_count": 1,
        "per_page": 10,
        "total_count": 2
      }
    }
    """

  @concurrent
  Scenario: given check event and enrich from external api data with unreachable host should create failure
    Given I am admin
    When I do POST /api/v4/eventfilter/rules:
    """json
    {
      "type": "enrichment",
      "description": "test-event-filter-che-event-filters-failure-api-2-description",
      "enabled": true,
      "event_pattern": [
        [
          {
            "field": "component",
            "cond": {
              "type": "eq",
              "value": "test-component-che-event-filters-failure-api-2"
            }
          },
          {
            "field": "event_type",
            "cond": {
              "type": "eq",
              "value": "check"
            }
          }
        ]
      ],
      "external_data": {
        "title": {
          "type": "api",
          "request": {
            "url": "http://unreachable.local",
            "method": "GET",
            "timeout": {
              "value": 1,
              "unit": "s"
            },
            "retry_count": 0
          }
        }
      },
      "config": {
        "actions": [
          {
            "type": "set_field_from_template",
            "name": "title",
            "value": "{{ `{{.ExternalData.title.title}}` }}"
          }
        ],
        "on_success": "pass",
        "on_failure": "pass"
      }
    }
    """
    Then the response code should be 201
    Then I save response ruleId={{ .lastResponse._id }}
    When I wait the next periodical process
    When I send an event and wait the end of event processing:
    """json
    [
      {
        "event_type": "check",
        "state": 2,
        "output": "test-output-che-event-filters-failure-api-2",
        "connector": "test-connector-che-event-filters-failure-api-2",
        "connector_name": "test-connector-name-che-event-filters-failure-api-2",
        "component": "test-component-che-event-filters-failure-api-2",
        "resource": "test-resource-che-event-filters-failure-api-2-1",
        "source_type": "resource"
      },
      {
        "event_type": "check",
        "state": 2,
        "output": "test-output-che-event-filters-failure-api-2",
        "connector": "test-connector-che-event-filters-failure-api-2",
        "connector_name": "test-connector-name-che-event-filters-failure-api-2",
        "component": "test-component-che-event-filters-failure-api-2",
        "resource": "test-resource-che-event-filters-failure-api-2-2",
        "source_type": "resource"
      }
    ]
    """
    When I do GET /api/v4/eventfilter/{{ .ruleId }}/failures until response code is 200 and body contains:
    """json
    {
      "data": [
        {
          "type": 3,
          "message": "external data \"title\" cannot be fetched: url GET http://unreachable.local cannot be connected",
          "event": {
            "connector": "test-connector-che-event-filters-failure-api-2",
            "connector_name": "test-connector-name-che-event-filters-failure-api-2",
            "component": "test-component-che-event-filters-failure-api-2",
            "source_type": "resource"
          },
          "unread": true
        },
        {
          "type": 3,
          "message": "external data \"title\" cannot be fetched: url GET http://unreachable.local cannot be connected",
          "event": {
            "connector": "test-connector-che-event-filters-failure-api-2",
            "connector_name": "test-connector-name-che-event-filters-failure-api-2",
            "component": "test-component-che-event-filters-failure-api-2",
            "source_type": "resource"
          },
          "unread": true
        }
      ],
      "meta": {
        "page": 1,
        "page_count": 1,
        "per_page": 10,
        "total_count": 2
      }
    }
    """

  @concurrent
  Scenario: given check event and enrich from external api data with not JSON response should create failure
    Given I am admin
    When I do POST /api/v4/eventfilter/rules:
    """json
    {
      "type": "enrichment",
      "description": "test-event-filter-che-event-filters-failure-api-3-description",
      "enabled": true,
      "event_pattern": [
        [
          {
            "field": "component",
            "cond": {
              "type": "eq",
              "value": "test-component-che-event-filters-failure-api-3"
            }
          },
          {
            "field": "event_type",
            "cond": {
              "type": "eq",
              "value": "check"
            }
          }
        ]
      ],
      "external_data": {
        "title": {
          "type": "api",
          "request": {
            "url": "{{ .dummyApiURL }}/webhook/request",
            "method": "POST",
            "payload": "plain string",
            "retry_count": 0
          }
        }
      },
      "config": {
        "actions": [
          {
            "type": "set_field_from_template",
            "name": "title",
            "value": "{{ `{{.ExternalData.title.title}}` }}"
          }
        ],
        "on_success": "pass",
        "on_failure": "pass"
      }
    }
    """
    Then the response code should be 201
    Then I save response ruleId={{ .lastResponse._id }}
    When I wait the next periodical process
    When I send an event and wait the end of event processing:
    """json
    [
      {
        "event_type": "check",
        "state": 2,
        "output": "test-output-che-event-filters-failure-api-3",
        "connector": "test-connector-che-event-filters-failure-api-3",
        "connector_name": "test-connector-name-che-event-filters-failure-api-3",
        "component": "test-component-che-event-filters-failure-api-3",
        "resource": "test-resource-che-event-filters-failure-api-3-1",
        "source_type": "resource"
      },
      {
        "event_type": "check",
        "state": 2,
        "output": "test-output-che-event-filters-failure-api-3",
        "connector": "test-connector-che-event-filters-failure-api-3",
        "connector_name": "test-connector-name-che-event-filters-failure-api-3",
        "component": "test-component-che-event-filters-failure-api-3",
        "resource": "test-resource-che-event-filters-failure-api-3-2",
        "source_type": "resource"
      }
    ]
    """
    When I do GET /api/v4/eventfilter/{{ .ruleId }}/failures until response code is 200 and body contains:
    """json
    {
      "data": [
        {
          "type": 3,
          "message": "external data \"title\" response in invalid: response of POST {{ .dummyApiURL }}/webhook/request is not valid JSON",
          "event": {
            "connector": "test-connector-che-event-filters-failure-api-3",
            "connector_name": "test-connector-name-che-event-filters-failure-api-3",
            "component": "test-component-che-event-filters-failure-api-3",
            "source_type": "resource"
          },
          "unread": true
        },
        {
          "type": 3,
          "message": "external data \"title\" response in invalid: response of POST {{ .dummyApiURL }}/webhook/request is not valid JSON",
          "event": {
            "connector": "test-connector-che-event-filters-failure-api-3",
            "connector_name": "test-connector-name-che-event-filters-failure-api-3",
            "component": "test-component-che-event-filters-failure-api-3",
            "source_type": "resource"
          },
          "unread": true
        }
      ],
      "meta": {
        "page": 1,
        "page_count": 1,
        "per_page": 10,
        "total_count": 2
      }
    }
    """

  @concurrent
  Scenario: given check event and enrich from external api data with invalid url template should create failure
    Given I am admin
    When I do POST /api/v4/eventfilter/rules:
    """json
    {
      "type": "enrichment",
      "description": "test-event-filter-che-event-filters-failure-api-4-description",
      "enabled": true,
      "event_pattern": [
        [
          {
            "field": "component",
            "cond": {
              "type": "eq",
              "value": "test-component-che-event-filters-failure-api-4"
            }
          },
          {
            "field": "event_type",
            "cond": {
              "type": "eq",
              "value": "check"
            }
          }
        ]
      ],
      "external_data": {
        "title": {
          "type": "api",
          "request": {
            "url": "{{ .dummyApiURL }}/webhook/request/{{ `{{ .Event.Resource` }}",
            "method": "POST"
          }
        }
      },
      "config": {
        "actions": [
          {
            "type": "set_field_from_template",
            "name": "title",
            "value": "{{ `{{.ExternalData.title.title}}` }}"
          }
        ],
        "on_success": "pass",
        "on_failure": "pass"
      }
    }
    """
    Then the response code should be 201
    Then I save response ruleId={{ .lastResponse._id }}
    When I wait the next periodical process
    When I send an event and wait the end of event processing:
    """json
    [
      {
        "event_type": "check",
        "state": 2,
        "output": "test-output-che-event-filters-failure-api-4",
        "connector": "test-connector-che-event-filters-failure-api-4",
        "connector_name": "test-connector-name-che-event-filters-failure-api-4",
        "component": "test-component-che-event-filters-failure-api-4",
        "resource": "test-resource-che-event-filters-failure-api-4-1",
        "source_type": "resource"
      },
      {
        "event_type": "check",
        "state": 2,
        "output": "test-output-che-event-filters-failure-api-4",
        "connector": "test-connector-che-event-filters-failure-api-4",
        "connector_name": "test-connector-name-che-event-filters-failure-api-4",
        "component": "test-component-che-event-filters-failure-api-4",
        "resource": "test-resource-che-event-filters-failure-api-4-2",
        "source_type": "resource"
      }
    ]
    """
    When I do GET /api/v4/eventfilter/{{ .ruleId }}/failures until response code is 200 and body contains:
    """json
    {
      "data": [
        {
          "type": 1,
          "message": "invalid template \"ExternalData.title.Request.URL\": template: tpl:1: unclosed action",
          "event": null,
          "unread": true
        },
        {
          "type": 1,
          "message": "invalid template \"ExternalData.title.Request.URL\": template: tpl:1: unclosed action",
          "event": null,
          "unread": true
        }
      ],
      "meta": {
        "page": 1,
        "page_count": 1,
        "per_page": 10,
        "total_count": 2
      }
    }
    """

  @concurrent
  Scenario: given check event and enrich from external api data with invalid payload template should create failure
    Given I am admin
    When I do POST /api/v4/eventfilter/rules:
    """json
    {
      "type": "enrichment",
      "description": "test-event-filter-che-event-filters-failure-api-5-description",
      "enabled": true,
      "event_pattern": [
        [
          {
            "field": "component",
            "cond": {
              "type": "eq",
              "value": "test-component-che-event-filters-failure-api-5"
            }
          },
          {
            "field": "event_type",
            "cond": {
              "type": "eq",
              "value": "check"
            }
          }
        ]
      ],
      "external_data": {
        "title": {
          "type": "api",
          "request": {
            "url": "{{ .dummyApiURL }}/webhook/request",
            "method": "POST",
            "payload": "{\"_id\":\"{{ `{{ .Event.Resource` }}\"}"
          }
        }
      },
      "config": {
        "actions": [
          {
            "type": "set_field_from_template",
            "name": "title",
            "value": "{{ `{{.ExternalData.title.title}}` }}"
          }
        ],
        "on_success": "pass",
        "on_failure": "pass"
      }
    }
    """
    Then the response code should be 201
    Then I save response ruleId={{ .lastResponse._id }}
    When I wait the next periodical process
    When I send an event and wait the end of event processing:
    """json
    [
      {
        "event_type": "check",
        "state": 2,
        "output": "test-output-che-event-filters-failure-api-5",
        "connector": "test-connector-che-event-filters-failure-api-5",
        "connector_name": "test-connector-name-che-event-filters-failure-api-5",
        "component": "test-component-che-event-filters-failure-api-5",
        "resource": "test-resource-che-event-filters-failure-api-5-1",
        "source_type": "resource"
      },
      {
        "event_type": "check",
        "state": 2,
        "output": "test-output-che-event-filters-failure-api-5",
        "connector": "test-connector-che-event-filters-failure-api-5",
        "connector_name": "test-connector-name-che-event-filters-failure-api-5",
        "component": "test-component-che-event-filters-failure-api-5",
        "resource": "test-resource-che-event-filters-failure-api-5-2",
        "source_type": "resource"
      }
    ]
    """
    When I do GET /api/v4/eventfilter/{{ .ruleId }}/failures until response code is 200 and body contains:
    """json
    {
      "data": [
        {
          "type": 1,
          "message": "invalid template \"ExternalData.title.Request.Payload\": template: tpl:1: bad character U+0022 '\"'",
          "event": null,
          "unread": true
        },
        {
          "type": 1,
          "message": "invalid template \"ExternalData.title.Request.Payload\": template: tpl:1: bad character U+0022 '\"'",
          "event": null,
          "unread": true
        }
      ],
      "meta": {
        "page": 1,
        "page_count": 1,
        "per_page": 10,
        "total_count": 2
      }
    }
    """

  @concurrent
  Scenario: given check event and enrich from external api data with not found url template var should create failure
    Given I am admin
    When I do POST /api/v4/eventfilter/rules:
    """json
    {
      "type": "enrichment",
      "description": "test-event-filter-che-event-filters-failure-api-6-description",
      "enabled": true,
      "event_pattern": [
        [
          {
            "field": "component",
            "cond": {
              "type": "eq",
              "value": "test-component-che-event-filters-failure-api-6"
            }
          },
          {
            "field": "event_type",
            "cond": {
              "type": "eq",
              "value": "check"
            }
          }
        ]
      ],
      "external_data": {
        "title": {
          "type": "api",
          "request": {
            "url": "{{ .dummyApiURL }}/webhook/request/{{ `{{ .Event.ExtraInfos.notfound }}` }}",
            "method": "POST"
          }
        }
      },
      "config": {
        "actions": [
          {
            "type": "set_field_from_template",
            "name": "title",
            "value": "{{ `{{.ExternalData.title.title}}` }}"
          }
        ],
        "on_success": "pass",
        "on_failure": "pass"
      }
    }
    """
    Then the response code should be 201
    Then I save response ruleId={{ .lastResponse._id }}
    When I wait the next periodical process
    When I send an event and wait the end of event processing:
    """json
    [
      {
        "event_type": "check",
        "state": 2,
        "output": "test-output-che-event-filters-failure-api-6",
        "connector": "test-connector-che-event-filters-failure-api-6",
        "connector_name": "test-connector-name-che-event-filters-failure-api-6",
        "component": "test-component-che-event-filters-failure-api-6",
        "resource": "test-resource-che-event-filters-failure-api-6-1",
        "source_type": "resource"
      },
      {
        "event_type": "check",
        "state": 2,
        "output": "test-output-che-event-filters-failure-api-6",
        "connector": "test-connector-che-event-filters-failure-api-6",
        "connector_name": "test-connector-name-che-event-filters-failure-api-6",
        "component": "test-component-che-event-filters-failure-api-6",
        "resource": "test-resource-che-event-filters-failure-api-6-2",
        "source_type": "resource"
      }
    ]
    """
    When I do GET /api/v4/eventfilter/{{ .ruleId }}/failures until response code is 200 and body contains:
    """json
    {
      "data": [
        {
          "type": 1,
          "message": "cannot execute template \"ExternalData.title.Request.URL\" for event: template: tpl:1:47: executing \"tpl\" at <.Event.ExtraInfos.notfound>: map has no entry for key \"notfound\"",
          "event": {
            "connector": "test-connector-che-event-filters-failure-api-6",
            "connector_name": "test-connector-name-che-event-filters-failure-api-6",
            "component": "test-component-che-event-filters-failure-api-6",
            "source_type": "resource"
          },
          "unread": true
        },
        {
          "type": 1,
          "message": "cannot execute template \"ExternalData.title.Request.URL\" for event: template: tpl:1:47: executing \"tpl\" at <.Event.ExtraInfos.notfound>: map has no entry for key \"notfound\"",
          "event": {
            "connector": "test-connector-che-event-filters-failure-api-6",
            "connector_name": "test-connector-name-che-event-filters-failure-api-6",
            "component": "test-component-che-event-filters-failure-api-6",
            "source_type": "resource"
          },
          "unread": true
        }
      ],
      "meta": {
        "page": 1,
        "page_count": 1,
        "per_page": 10,
        "total_count": 2
      }
    }
    """

  @concurrent
  Scenario: given check event and enrich from external api data with invalid payload template should create failure
    Given I am admin
    When I do POST /api/v4/eventfilter/rules:
    """json
    {
      "type": "enrichment",
      "description": "test-event-filter-che-event-filters-failure-api-7-description",
      "enabled": true,
      "event_pattern": [
        [
          {
            "field": "component",
            "cond": {
              "type": "eq",
              "value": "test-component-che-event-filters-failure-api-7"
            }
          },
          {
            "field": "event_type",
            "cond": {
              "type": "eq",
              "value": "check"
            }
          }
        ]
      ],
      "external_data": {
        "title": {
          "type": "api",
          "request": {
            "url": "{{ .dummyApiURL }}/webhook/request",
            "method": "POST",
            "payload": "{\"_id\":\"{{ `{{ .Event.ExtraInfos.notfound }}` }}\"}"
          }
        }
      },
      "config": {
        "actions": [
          {
            "type": "set_field_from_template",
            "name": "title",
            "value": "{{ `{{.ExternalData.title.title}}` }}"
          }
        ],
        "on_success": "pass",
        "on_failure": "pass"
      }
    }
    """
    Then the response code should be 201
    Then I save response ruleId={{ .lastResponse._id }}
    When I wait the next periodical process
    When I send an event and wait the end of event processing:
    """json
    [
      {
        "event_type": "check",
        "state": 2,
        "output": "test-output-che-event-filters-failure-api-7",
        "connector": "test-connector-che-event-filters-failure-api-7",
        "connector_name": "test-connector-name-che-event-filters-failure-api-7",
        "component": "test-component-che-event-filters-failure-api-7",
        "resource": "test-resource-che-event-filters-failure-api-7-1",
        "source_type": "resource"
      },
      {
        "event_type": "check",
        "state": 2,
        "output": "test-output-che-event-filters-failure-api-7",
        "connector": "test-connector-che-event-filters-failure-api-7",
        "connector_name": "test-connector-name-che-event-filters-failure-api-7",
        "component": "test-component-che-event-filters-failure-api-7",
        "resource": "test-resource-che-event-filters-failure-api-7-2",
        "source_type": "resource"
      }
    ]
    """
    When I do GET /api/v4/eventfilter/{{ .ruleId }}/failures until response code is 200 and body contains:
    """json
    {
      "data": [
        {
          "type": 1,
          "message": "cannot execute template \"ExternalData.title.Request.Payload\" for event: template: tpl:1:17: executing \"tpl\" at <.Event.ExtraInfos.notfound>: map has no entry for key \"notfound\"",
          "event": {
            "connector": "test-connector-che-event-filters-failure-api-7",
            "connector_name": "test-connector-name-che-event-filters-failure-api-7",
            "component": "test-component-che-event-filters-failure-api-7",
            "source_type": "resource"
          },
          "unread": true
        },
        {
          "type": 1,
          "message": "cannot execute template \"ExternalData.title.Request.Payload\" for event: template: tpl:1:17: executing \"tpl\" at <.Event.ExtraInfos.notfound>: map has no entry for key \"notfound\"",
          "event": {
            "connector": "test-connector-che-event-filters-failure-api-7",
            "connector_name": "test-connector-name-che-event-filters-failure-api-7",
            "component": "test-component-che-event-filters-failure-api-7",
            "source_type": "resource"
          },
          "unread": true
        }
      ],
      "meta": {
        "page": 1,
        "page_count": 1,
        "per_page": 10,
        "total_count": 2
      }
    }
    """

  @concurrent
  Scenario: given check event and enrich from external api data with invalid method should create failure
    Given I am admin
    Then I save response ruleId=test-event-filter-che-event-filters-failure-api-8
    When I send an event and wait the end of event processing:
    """json
    [
      {
        "event_type": "check",
        "state": 2,
        "output": "test-output-che-event-filters-failure-api-8",
        "connector": "test-connector-che-event-filters-failure-api-8",
        "connector_name": "test-connector-name-che-event-filters-failure-api-8",
        "component": "test-component-che-event-filters-failure-api-8",
        "resource": "test-resource-che-event-filters-failure-api-8-1",
        "source_type": "resource"
      },
      {
        "event_type": "check",
        "state": 2,
        "output": "test-output-che-event-filters-failure-api-8",
        "connector": "test-connector-che-event-filters-failure-api-8",
        "connector_name": "test-connector-name-che-event-filters-failure-api-8",
        "component": "test-component-che-event-filters-failure-api-8",
        "resource": "test-resource-che-event-filters-failure-api-8-2",
        "source_type": "resource"
      }
    ]
    """
    When I do GET /api/v4/eventfilter/{{ .ruleId }}/failures until response code is 200 and body contains:
    """json
    {
      "data": [
        {
          "type": 3,
          "message": "external data \"title\" has invalid request parameters: net/http: invalid method \"?INVALID?\"",
          "event": null,
          "unread": true
        },
        {
          "type": 3,
          "message": "external data \"title\" has invalid request parameters: net/http: invalid method \"?INVALID?\"",
          "event": null,
          "unread": true
        }
      ],
      "meta": {
        "page": 1,
        "page_count": 1,
        "per_page": 10,
        "total_count": 2
      }
    }
    """

  @concurrent
  Scenario: given check event and enrich from external api data with empty request should create failure
    Given I am admin
    Then I save response ruleId=test-event-filter-che-event-filters-failure-api-9
    When I send an event and wait the end of event processing:
    """json
    [
      {
        "event_type": "check",
        "state": 2,
        "output": "test-output-che-event-filters-failure-api-9",
        "connector": "test-connector-che-event-filters-failure-api-9",
        "connector_name": "test-connector-name-che-event-filters-failure-api-9",
        "component": "test-component-che-event-filters-failure-api-9",
        "resource": "test-resource-che-event-filters-failure-api-9-1",
        "source_type": "resource"
      },
      {
        "event_type": "check",
        "state": 2,
        "output": "test-output-che-event-filters-failure-api-9",
        "connector": "test-connector-che-event-filters-failure-api-9",
        "connector_name": "test-connector-name-che-event-filters-failure-api-9",
        "component": "test-component-che-event-filters-failure-api-9",
        "resource": "test-resource-che-event-filters-failure-api-9-2",
        "source_type": "resource"
      }
    ]
    """
    When I do GET /api/v4/eventfilter/{{ .ruleId }}/failures until response code is 200 and body contains:
    """json
    {
      "data": [
        {
          "type": 3,
          "message": "external data \"title\" has empty request parameters",
          "event": null,
          "unread": true
        },
        {
          "type": 3,
          "message": "external data \"title\" has empty request parameters",
          "event": null,
          "unread": true
        }
      ],
      "meta": {
        "page": 1,
        "page_count": 1,
        "per_page": 10,
        "total_count": 2
      }
    }
    """
